Workbook

Sheet Instructions
B2: Upload in webshop at: https://srvweb.microsynth.ch/ | H2: AP
B3: In case of problems send order to: oligo.support@microsynth.ch | H3: EXP
H4: DHL
B5: Microsynth AG, Switzerland
B6: Schützenstrasse 15 • CH-9436 Balgach
B7: Phone +41 71 722 83 33 • oligo.support@microsynth.ch • www.microsynth.com
B9: Last modification: 17.06.2025
B10: Version V6.0.5
B13: Microsynth Excel Order Form
B15: General Informations:
B17: ● The minimal number of oligonucleotides delivered in deep well plates is 32.
B18: ● Four columns are mandatory: Oligo name, Sequence, Purification, Scale (and Modifications, if applicable).
B19: ● Do not use the character(s) ; " , in the oligo names. The Oligo name should not be longer than 35 characters.
B20: ● Please refer strictly to the abbreviations given in the pull-down menus.
B21: ● Please obey the rules given in the cell comments.
... B37: ● Length restrictions for DNA synthesis scales:
C38: ="○ Genomics: " & dataValidation!T3 & " - " & dataValidation!U3 & "mer"
C39: ="○ " & dataValidation!S4 & " µmol: " & dataValidation!T4 & " - " & dataValidation!U4 & "mer"
C40: ="○ " & dataValidation!S5 & " µmol: " & dataValidation!T5 & " - " & dataValidation!U5 & "mer"
C41: ="○ " & dataValidation!S6 & " µmol: " & dataValidation!T6 & " - " & dataValidation!U6 & "mer"
C42: ="○ " & dataValidation!S7 & " µmol: " & dataValidation!T7 & " - " & dataValidation!U7 & "mer"

Sheet DNA Order
A1: DNA Oligo Name | B1: DNA Sequence (5' -> 3') | C1: Length | D1: DNA Purification | E1: DNA Scale | F1: 5' Modification | G1: Inner Modification (5) | H1: Inner Modification (6) | I1: Inner Modification (7) | J1: Inner Modification (8) | K1: 3' Modification | L1: Physical Condition | M1: Datasheet | N1: Aliquots | P1: Length | Q1: check empty name | R1: check empty sequence | S1: check scale | T1: check scale/purification | U1: check name length | V1: check name characters | W1: check sequence characters | X1: allowed exception scale | Y1: allowed exception scale/purification | Z1: allowed condition 1 | AA1: allowed condition 2 | AC1: check physical condition | AD1: check datasheet | AE1: check aliquot
A2: RT-cdh1 1F | B2: GAAGATCACGTATCGGATTTGG | C2: 22 | O2: =Q2 & R2 & U2 & V2 & W2 & S2 & T2 & AC2 & AD2 & AE2 | P2: =IF(B2<>"",LEN(SUBSTITUTE(SUBSTITUTE(B2," ",""),"*","")),"") | Q2: =IF(AND(A2="",B2<>""),"No name provided. ","") | R2: =IF(AND(A2<>"",B2=""),"No sequence provided. ","") | S2: =IF(AND(P2<>"",E2<>"",NOT(X2)),IF(AND(INDEX(validDnaScaleLowerSizeLimits,MATCH(E2,validDnaScale,0))<=$P2,$P2<=INDEX(validDnaScaleUpperSizeLimits,MATCH(E2,validDnaScale,0))),"","Sequence (length) not available in " & E2 & " scale. "),"") | T2: =IF(AND(P2<>"",E2<>"",NOT(Y2)),IF(AND(INDEX(validDnaPurificationLowerSizeLimits,MATCH(E2,validDnaScale,0),MATCH(D2,validDnaPurificationLowerSizeLimitsHeader,0))<=$P2,$P2<=INDEX(validDnaPurificationUpperSizeLimits,MATCH(E2,validDnaScale,0),MATCH(D2,validDnaPurificationUpperSizeLimitsHeader,0))),"","Combination of purification and scale not available. "),"") | U2: =IF(LEN(A2)>validOligoNameMaxLength,"DNA oligo name is too long. ","") | V2: =IF(AND(A2<>"",NOT(ISNUMBER(SUMPRODUCT(FIND(MID(A2,ROW(INDIRECT("1:"&LEN(A2))),1),validOligoNameCharacters))))),"DNA oligo name contains invalid characters. ","") | W2: =IF(AND(B2<>"",NOT(ISNUMBER(SUMPRODUCT(FIND(MID(B2,ROW(INDIRECT("1:"&LEN(B2))),1),validDnaSequenceCharacters))))),"DNA sequence contains invalid characters. ","") | X2: =OR(Z2,AA2) | Y2: =OR(Z2,AA2) | Z2: =AND(A2="Leerposition",P2>=2) | AA2: =AND(LEFT(A2,4)="NGS_",P2<=65,OR(D2="HPL",D2="HPD")) | AC2: =IF(AND(A2<>"",L2=""),"Physical condition not defined. ","") | AD2: =IF(AND(A2<>"",M2=""),"Datasheet not defined. ","") | AE2: =IF(AND(A2<>"",N2=""),"Aliquoting not defined. ","")
A3: RT-cdh1 1R | B3: GTTTCGAGGTTCTGGGATGG | C3: 20 | O3: =Q3 & R3 & U3 & V3 & W3 & S3 & T3 & AC3 & AD3 & AE3 | P3: =IF(B3<>"",LEN(SUBSTITUTE(SUBSTITUTE(B3," ",""),"*","")),"") | Q3: =IF(AND(A3="",B3<>""),"No name provided. ","") | R3: =IF(AND(A3<>"",B3=""),"No sequence provided. ","") | S3: =IF(AND(P3<>"",E3<>"",NOT(X3)),IF(AND(INDEX(validDnaScaleLowerSizeLimits,MATCH(E3,validDnaScale,0))<=$P3,$P3<=INDEX(validDnaScaleUpperSizeLimits,MATCH(E3,validDnaScale,0))),"","Sequence (length) not available in " & E3 & " scale. "),"") | T3: =IF(AND(P3<>"",E3<>"",NOT(Y3)),IF(AND(INDEX(validDnaPurificationLowerSizeLimits,MATCH(E3,validDnaScale,0),MATCH(D3,validDnaPurificationLowerSizeLimitsHeader,0))<=$P3,$P3<=INDEX(validDnaPurificationUpperSizeLimits,MATCH(E3,validDnaScale,0),MATCH(D3,validDnaPurificationUpperSizeLimitsHeader,0))),"","Combination of purification and scale not available. "),"") | U3: =IF(LEN(A3)>validOligoNameMaxLength,"DNA oligo name is too long. ","") | V3: =IF(AND(A3<>"",NOT(ISNUMBER(SUMPRODUCT(FIND(MID(A3,ROW(INDIRECT("1:"&LEN(A3))),1),validOligoNameCharacters))))),"DNA oligo name contains invalid characters. ","") | W3: =IF(AND(B3<>"",NOT(ISNUMBER(SUMPRODUCT(FIND(MID(B3,ROW(INDIRECT("1:"&LEN(B3))),1),validDnaSequenceCharacters))))),"DNA sequence contains invalid characters. ","") | X3: =OR(Z3,AA3) | Y3: =OR(Z3,AA3) | Z3: =AND(A3="Leerposition",P3>=2) | AA3: =AND(LEFT(A3,4)="NGS_",P3<=65,OR(D3="HPL",D3="HPD")) | AC3: =IF(AND(A3<>"",L3=""),"Physical condition not defined. ","") | AD3: =IF(AND(A3<>"",M3=""),"Datasheet not defined. ","") | AE3: =IF(AND(A3<>"",N3=""),"Aliquoting not defined. ","")
A4: RT-cdh1 2F | B4: AAGATCACGTATCGGATTTGG | C4: 21 | O4: =Q4 & R4 & U4 & V4 & W4 & S4 & T4 & AC4 & AD4 & AE4 | P4: =IF(B4<>"",LEN(SUBSTITUTE(SUBSTITUTE(B4," ",""),"*","")),"") | Q4: =IF(AND(A4="",B4<>""),"No name provided. ","") | R4: =IF(AND(A4<>"",B4=""),"No sequence provided. ","") | S4: =IF(AND(P4<>"",E4<>"",NOT(X4)),IF(AND(INDEX(validDnaScaleLowerSizeLimits,MATCH(E4,validDnaScale,0))<=$P4,$P4<=INDEX(validDnaScaleUpperSizeLimits,MATCH(E4,validDnaScale,0))),"","Sequence (length) not available in " & E4 & " scale. "),"") | T4: =IF(AND(P4<>"",E4<>"",NOT(Y4)),IF(AND(INDEX(validDnaPurificationLowerSizeLimits,MATCH(E4,validDnaScale,0),MATCH(D4,validDnaPurificationLowerSizeLimitsHeader,0))<=$P4,$P4<=INDEX(validDnaPurificationUpperSizeLimits,MATCH(E4,validDnaScale,0),MATCH(D4,validDnaPurificationUpperSizeLimitsHeader,0))),"","Combination of purification and scale not available. "),"") | U4: =IF(LEN(A4)>validOligoNameMaxLength,"DNA oligo name is too long. ","") | V4: =IF(AND(A4<>"",NOT(ISNUMBER(SUMPRODUCT(FIND(MID(A4,ROW(INDIRECT("1:"&LEN(A4))),1),validOligoNameCharacters))))),"DNA oligo name contains invalid characters. ","") | W4: =IF(AND(B4<>"",NOT(ISNUMBER(SUMPRODUCT(FIND(MID(B4,ROW(INDIRECT("1:"&LEN(B4))),1),validDnaSequenceCharacters))))),"DNA sequence contains invalid characters. ","") | X4: =OR(Z4,AA4) | Y4: =OR(Z4,AA4) | Z4: =AND(A4="Leerposition",P4>=2) | AA4: =AND(LEFT(A4,4)="NGS_",P4<=65,OR(D4="HPL",D4="HPD")) | AC4: =IF(AND(A4<>"",L4=""),"Physical condition not defined. ","") | AD4: =IF(AND(A4<>"",M4=""),"Datasheet not defined. ","") | AE4: =IF(AND(A4<>"",N4=""),"Aliquoting not defined. ","")
A5: RT-cdh1 2R | B5: GTTTCGAGGTTCTGGGATGG | C5: 20 | O5: =Q5 & R5 & U5 & V5 & W5 & S5 & T5 & AC5 & AD5 & AE5 | P5: =IF(B5<>"",LEN(SUBSTITUTE(SUBSTITUTE(B5," ",""),"*","")),"") | Q5: =IF(AND(A5="",B5<>""),"No name provided. ","") | R5: =IF(AND(A5<>"",B5=""),"No sequence provided. ","") | S5: =IF(AND(P5<>"",E5<>"",NOT(X5)),IF(AND(INDEX(validDnaScaleLowerSizeLimits,MATCH(E5,validDnaScale,0))<=$P5,$P5<=INDEX(validDnaScaleUpperSizeLimits,MATCH(E5,validDnaScale,0))),"","Sequence (length) not available in " & E5 & " scale. "),"") | T5: =IF(AND(P5<>"",E5<>"",NOT(Y5)),IF(AND(INDEX(validDnaPurificationLowerSizeLimits,MATCH(E5,validDnaScale,0),MATCH(D5,validDnaPurificationLowerSizeLimitsHeader,0))<=$P5,$P5<=INDEX(validDnaPurificationUpperSizeLimits,MATCH(E5,validDnaScale,0),MATCH(D5,validDnaPurificationUpperSizeLimitsHeader,0))),"","Combination of purification and scale not available. "),"") | U5: =IF(LEN(A5)>validOligoNameMaxLength,"DNA oligo name is too long. ","") | V5: =IF(AND(A5<>"",NOT(ISNUMBER(SUMPRODUCT(FIND(MID(A5,ROW(INDIRECT("1:"&LEN(A5))),1),validOligoNameCharacters))))),"DNA oligo name contains invalid characters. ","") | W5: =IF(AND(B5<>"",NOT(ISNUMBER(SUMPRODUCT(FIND(MID(B5,ROW(INDIRECT("1:"&LEN(B5))),1),validDnaSequenceCharacters))))),"DNA sequence contains invalid characters. ","") | X5: =OR(Z5,AA5) | Y5: =OR(Z5,AA5) | Z5: =AND(A5="Leerposition",P5>=2) | AA5: =AND(LEFT(A5,4)="NGS_",P5<=65,OR(D5="HPL",D5="HPD")) | AC5: =IF(AND(A5<>"",L5=""),"Physical condition not defined. ","") | AD5: =IF(AND(A5<>"",M5=""),"Datasheet not defined. ","") | AE5: =IF(AND(A5<>"",N5=""),"Aliquoting not defined. ","")
C6: =IF(B6<>"",LEN(SUBSTITUTE(SUBSTITUTE(B6," ",""),"*","")),"") | O6: =Q6 & R6 & U6 & V6 & W6 & S6 & T6 & AC6 & AD6 & AE6 | P6: =IF(B6<>"",LEN(SUBSTITUTE(SUBSTITUTE(B6," ",""),"*","")),"") | Q6: =IF(AND(A6="",B6<>""),"No name provided. ","") | R6: =IF(AND(A6<>"",B6=""),"No sequence provided. ","") | S6: =IF(AND(P6<>"",E6<>"",NOT(X6)),IF(AND(INDEX(validDnaScaleLowerSizeLimits,MATCH(E6,validDnaScale,0))<=$P6,$P6<=INDEX(validDnaScaleUpperSizeLimits,MATCH(E6,validDnaScale,0))),"","Sequence (length) not available in " & E6 & " scale. "),"") | T6: =IF(AND(P6<>"",E6<>"",NOT(Y6)),IF(AND(INDEX(validDnaPurificationLowerSizeLimits,MATCH(E6,validDnaScale,0),MATCH(D6,validDnaPurificationLowerSizeLimitsHeader,0))<=$P6,$P6<=INDEX(validDnaPurificationUpperSizeLimits,MATCH(E6,validDnaScale,0),MATCH(D6,validDnaPurificationUpperSizeLimitsHeader,0))),"","Combination of purification and scale not available. "),"") | U6: =IF(LEN(A6)>validOligoNameMaxLength,"DNA oligo name is too long. ","") | V6: =IF(AND(A6<>"",NOT(ISNUMBER(SUMPRODUCT(FIND(MID(A6,ROW(INDIRECT("1:"&LEN(A6))),1),validOligoNameCharacters))))),"DNA oligo name contains invalid characters. ","") | W6: =IF(AND(B6<>"",NOT(ISNUMBER(SUMPRODUCT(FIND(MID(B6,ROW(INDIRECT("1:"&LEN(B6))),1),validDnaSequenceCharacters))))),"DNA sequence contains invalid characters. ","") | X6: =OR(Z6,AA6) | Y6: =OR(Z6,AA6) | Z6: =AND(A6="Leerposition",P6>=2) | AA6: =AND(LEFT(A6,4)="NGS_",P6<=65,OR(D6="HPL",D6="HPD")) | AC6: =IF(AND(A6<>"",L6=""),"Physical condition not defined. ","") | AD6: =IF(AND(A6<>"",M6=""),"Datasheet not defined. ","") | AE6: =IF(AND(A6<>"",N6=""),"Aliquoting not defined. ","")
C7: =IF(B7<>"",LEN(SUBSTITUTE(SUBSTITUTE(B7," ",""),"*","")),"") | O7: =Q7 & R7 & U7 & V7 & W7 & S7 & T7 & AC7 & AD7 & AE7 | P7: =IF(B7<>"",LEN(SUBSTITUTE(SUBSTITUTE(B7," ",""),"*","")),"") | Q7: =IF(AND(A7="",B7<>""),"No name provided. ","") | R7: =IF(AND(A7<>"",B7=""),"No sequence provided. ","") | S7: =IF(AND(P7<>"",E7<>"",NOT(X7)),IF(AND(INDEX(validDnaScaleLowerSizeLimits,MATCH(E7,validDnaScale,0))<=$P7,$P7<=INDEX(validDnaScaleUpperSizeLimits,MATCH(E7,validDnaScale,0))),"","Sequence (length) not available in " & E7 & " scale. "),"") | T7: =IF(AND(P7<>"",E7<>"",NOT(Y7)),IF(AND(INDEX(validDnaPurificationLowerSizeLimits,MATCH(E7,validDnaScale,0),MATCH(D7,validDnaPurificationLowerSizeLimitsHeader,0))<=$P7,$P7<=INDEX(validDnaPurificationUpperSizeLimits,MATCH(E7,validDnaScale,0),MATCH(D7,validDnaPurificationUpperSizeLimitsHeader,0))),"","Combination of purification and scale not available. "),"") | U7: =IF(LEN(A7)>validOligoNameMaxLength,"DNA oligo name is too long. ","") | V7: =IF(AND(A7<>"",NOT(ISNUMBER(SUMPRODUCT(FIND(MID(A7,ROW(INDIRECT("1:"&LEN(A7))),1),validOligoNameCharacters))))),"DNA oligo name contains invalid characters. ","") | W7: =IF(AND(B7<>"",NOT(ISNUMBER(SUMPRODUCT(FIND(MID(B7,ROW(INDIRECT("1:"&LEN(B7))),1),validDnaSequenceCharacters))))),"DNA sequence contains invalid characters. ","") | X7: =OR(Z7,AA7) | Y7: =OR(Z7,AA7) | Z7: =AND(A7="Leerposition",P7>=2) | AA7: =AND(LEFT(A7,4)="NGS_",P7<=65,OR(D7="HPL",D7="HPD")) | AC7: =IF(AND(A7<>"",L7=""),"Physical condition not defined. ","") | AD7: =IF(AND(A7<>"",M7=""),"Datasheet not defined. ","") | AE7: =IF(AND(A7<>"",N7=""),"Aliquoting not defined. ","")
C8: =IF(B8<>"",LEN(SUBSTITUTE(SUBSTITUTE(B8," ",""),"*","")),"") | O8: =Q8 & R8 & U8 & V8 & W8 & S8 & T8 & AC8 & AD8 & AE8 | P8: =IF(B8<>"",LEN(SUBSTITUTE(SUBSTITUTE(B8," ",""),"*","")),"") | Q8: =IF(AND(A8="",B8<>""),"No name provided. ","") | R8: =IF(AND(A8<>"",B8=""),"No sequence provided. ","") | S8: =IF(AND(P8<>"",E8<>"",NOT(X8)),IF(AND(INDEX(validDnaScaleLowerSizeLimits,MATCH(E8,validDnaScale,0))<=$P8,$P8<=INDEX(validDnaScaleUpperSizeLimits,MATCH(E8,validDnaScale,0))),"","Sequence (length) not available in " & E8 & " scale. "),"") | T8: =IF(AND(P8<>"",E8<>"",NOT(Y8)),IF(AND(INDEX(validDnaPurificationLowerSizeLimits,MATCH(E8,validDnaScale,0),MATCH(D8,validDnaPurificationLowerSizeLimitsHeader,0))<=$P8,$P8<=INDEX(validDnaPurificationUpperSizeLimits,MATCH(E8,validDnaScale,0),MATCH(D8,validDnaPurificationUpperSizeLimitsHeader,0))),"","Combination of purification and scale not available. "),"") | U8: =IF(LEN(A8)>validOligoNameMaxLength,"DNA oligo name is too long. ","") | V8: =IF(AND(A8<>"",NOT(ISNUMBER(SUMPRODUCT(FIND(MID(A8,ROW(INDIRECT("1:"&LEN(A8))),1),validOligoNameCharacters))))),"DNA oligo name contains invalid characters. ","") | W8: =IF(AND(B8<>"",NOT(ISNUMBER(SUMPRODUCT(FIND(MID(B8,ROW(INDIRECT("1:"&LEN(B8))),1),validDnaSequenceCharacters))))),"DNA sequence contains invalid characters. ","") | X8: =OR(Z8,AA8) | Y8: =OR(Z8,AA8) | Z8: =AND(A8="Leerposition",P8>=2) | AA8: =AND(LEFT(A8,4)="NGS_",P8<=65,OR(D8="HPL",D8="HPD")) | AC8: =IF(AND(A8<>"",L8=""),"Physical condition not defined. ","") | AD8: =IF(AND(A8<>"",M8=""),"Datasheet not defined. ","") | AE8: =IF(AND(A8<>"",N8=""),"Aliquoting not defined. ","")
C9: =IF(B9<>"",LEN(SUBSTITUTE(SUBSTITUTE(B9," ",""),"*","")),"") | O9: =Q9 & R9 & U9 & V9 & W9 & S9 & T9 & AC9 & AD9 & AE9 | P9: =IF(B9<>"",LEN(SUBSTITUTE(SUBSTITUTE(B9," ",""),"*","")),"") | Q9: =IF(AND(A9="",B9<>""),"No name provided. ","") | R9: =IF(AND(A9<>"",B9=""),"No sequence provided. ","") | S9: =IF(AND(P9<>"",E9<>"",NOT(X9)),IF(AND(INDEX(validDnaScaleLowerSizeLimits,MATCH(E9,validDnaScale,0))<=$P9,$P9<=INDEX(validDnaScaleUpperSizeLimits,MATCH(E9,validDnaScale,0))),"","Sequence (length) not available in " & E9 & " scale. "),"") | T9: =IF(AND(P9<>"",E9<>"",NOT(Y9)),IF(AND(INDEX(validDnaPurificationLowerSizeLimits,MATCH(E9,validDnaScale,0),MATCH(D9,validDnaPurificationLowerSizeLimitsHeader,0))<=$P9,$P9<=INDEX(validDnaPurificationUpperSizeLimits,MATCH(E9,validDnaScale,0),MATCH(D9,validDnaPurificationUpperSizeLimitsHeader,0))),"","Combination of purification and scale not available. "),"") | U9: =IF(LEN(A9)>validOligoNameMaxLength,"DNA oligo name is too long. ","") | V9: =IF(AND(A9<>"",NOT(ISNUMBER(SUMPRODUCT(FIND(MID(A9,ROW(INDIRECT("1:"&LEN(A9))),1),validOligoNameCharacters))))),"DNA oligo name contains invalid characters. ","") | W9: =IF(AND(B9<>"",NOT(ISNUMBER(SUMPRODUCT(FIND(MID(B9,ROW(INDIRECT("1:"&LEN(B9))),1),validDnaSequenceCharacters))))),"DNA sequence contains invalid characters. ","") | X9: =OR(Z9,AA9) | Y9: =OR(Z9,AA9) | Z9: =AND(A9="Leerposition",P9>=2) | AA9: =AND(LEFT(A9,4)="NGS_",P9<=65,OR(D9="HPL",D9="HPD")) | AC9: =IF(AND(A9<>"",L9=""),"Physical condition not defined. ","") | AD9: =IF(AND(A9<>"",M9=""),"Datasheet not defined. ","") | AE9: =IF(AND(A9<>"",N9=""),"Aliquoting not defined. ","")
C10: =IF(B10<>"",LEN(SUBSTITUTE(SUBSTITUTE(B10," ",""),"*","")),"") | O10: =Q10 & R10 & U10 & V10 & W10 & S10 & T10 & AC10 & AD10 & AE10 | P10: =IF(B10<>"",LEN(SUBSTITUTE(SUBSTITUTE(B10," ",""),"*","")),"") | Q10: =IF(AND(A10="",B10<>""),"No name provided. ","") | R10: =IF(AND(A10<>"",B10=""),"No sequence provided. ","") | S10: =IF(AND(P10<>"",E10<>"",NOT(X10)),IF(AND(INDEX(validDnaScaleLowerSizeLimits,MATCH(E10,validDnaScale,0))<=$P10,$P10<=INDEX(validDnaScaleUpperSizeLimits,MATCH(E10,validDnaScale,0))),"","Sequence (length) not available in " & E10 & " scale. "),"") | T10: =IF(AND(P10<>"",E10<>"",NOT(Y10)),IF(AND(INDEX(validDnaPurificationLowerSizeLimits,MATCH(E10,validDnaScale,0),MATCH(D10,validDnaPurificationLowerSizeLimitsHeader,0))<=$P10,$P10<=INDEX(validDnaPurificationUpperSizeLimits,MATCH(E10,validDnaScale,0),MATCH(D10,validDnaPurificationUpperSizeLimitsHeader,0))),"","Combination of purification and scale not available. "),"") | U10: =IF(LEN(A10)>validOligoNameMaxLength,"DNA oligo name is too long. ","") | V10: =IF(AND(A10<>"",NOT(ISNUMBER(SUMPRODUCT(FIND(MID(A10,ROW(INDIRECT("1:"&LEN(A10))),1),validOligoNameCharacters))))),"DNA oligo name contains invalid characters. ","") | W10: =IF(AND(B10<>"",NOT(ISNUMBER(SUMPRODUCT(FIND(MID(B10,ROW(INDIRECT("1:"&LEN(B10))),1),validDnaSequenceCharacters))))),"DNA sequence contains invalid characters. ","") | X10: =OR(Z10,AA10) | Y10: =OR(Z10,AA10) | Z10: =AND(A10="Leerposition",P10>=2) | AA10: =AND(LEFT(A10,4)="NGS_",P10<=65,OR(D10="HPL",D10="HPD")) | AC10: =IF(AND(A10<>"",L10=""),"Physical condition not defined. ","") | AD10: =IF(AND(A10<>"",M10=""),"Datasheet not defined. ","") | AE10: =IF(AND(A10<>"",N10=""),"Aliquoting not defined. ","")
C11: =IF(B11<>"",LEN(SUBSTITUTE(SUBSTITUTE(B11," ",""),"*","")),"") | O11: =Q11 & R11 & U11 & V11 & W11 & S11 & T11 & AC11 & AD11 & AE11 | P11: =IF(B11<>"",LEN(SUBSTITUTE(SUBSTITUTE(B11," ",""),"*","")),"") | Q11: =IF(AND(A11="",B11<>""),"No name provided. ","") | R11: =IF(AND(A11<>"",B11=""),"No sequence provided. ","") | S11: =IF(AND(P11<>"",E11<>"",NOT(X11)),IF(AND(INDEX(validDnaScaleLowerSizeLimits,MATCH(E11,validDnaScale,0))<=$P11,$P11<=INDEX(validDnaScaleUpperSizeLimits,MATCH(E11,validDnaScale,0))),"","Sequence (length) not available in " & E11 & " scale. "),"") | T11: =IF(AND(P11<>"",E11<>"",NOT(Y11)),IF(AND(INDEX(validDnaPurificationLowerSizeLimits,MATCH(E11,validDnaScale,0),MATCH(D11,validDnaPurificationLowerSizeLimitsHeader,0))<=$P11,$P11<=INDEX(validDnaPurificationUpperSizeLimits,MATCH(E11,validDnaScale,0),MATCH(D11,validDnaPurificationUpperSizeLimitsHeader,0))),"","Combination of purification and scale not available. "),"") | U11: =IF(LEN(A11)>validOligoNameMaxLength,"DNA oligo name is too long. ","") | V11: =IF(AND(A11<>"",NOT(ISNUMBER(SUMPRODUCT(FIND(MID(A11,ROW(INDIRECT("1:"&LEN(A11))),1),validOligoNameCharacters))))),"DNA oligo name contains invalid characters. ","") | W11: =IF(AND(B11<>"",NOT(ISNUMBER(SUMPRODUCT(FIND(MID(B11,ROW(INDIRECT("1:"&LEN(B11))),1),validDnaSequenceCharacters))))),"DNA sequence contains invalid characters. ","") | X11: =OR(Z11,AA11) | Y11: =OR(Z11,AA11) | Z11: =AND(A11="Leerposition",P11>=2) | AA11: =AND(LEFT(A11,4)="NGS_",P11<=65,OR(D11="HPL",D11="HPD")) | AC11: =IF(AND(A11<>"",L11=""),"Physical condition not defined. ","") | AD11: =IF(AND(A11<>"",M11=""),"Datasheet not defined. ","") | AE11: =IF(AND(A11<>"",N11=""),"Aliquoting not defined. ","")
C12: =IF(B12<>"",LEN(SUBSTITUTE(SUBSTITUTE(B12," ",""),"*","")),"") | O12: =Q12 & R12 & U12 & V12 & W12 & S12 & T12 & AC12 & AD12 & AE12 | P12: =IF(B12<>"",LEN(SUBSTITUTE(SUBSTITUTE(B12," ",""),"*","")),"") | Q12: =IF(AND(A12="",B12<>""),"No name provided. ","") | R12: =IF(AND(A12<>"",B12=""),"No sequence provided. ","") | S12: =IF(AND(P12<>"",E12<>"",NOT(X12)),IF(AND(INDEX(validDnaScaleLowerSizeLimits,MATCH(E12,validDnaScale,0))<=$P12,$P12<=INDEX(validDnaScaleUpperSizeLimits,MATCH(E12,validDnaScale,0))),"","Sequence (length) not available in " & E12 & " scale. "),"") | T12: =IF(AND(P12<>"",E12<>"",NOT(Y12)),IF(AND(INDEX(validDnaPurificationLowerSizeLimits,MATCH(E12,validDnaScale,0),MATCH(D12,validDnaPurificationLowerSizeLimitsHeader,0))<=$P12,$P12<=INDEX(validDnaPurificationUpperSizeLimits,MATCH(E12,validDnaScale,0),MATCH(D12,validDnaPurificationUpperSizeLimitsHeader,0))),"","Combination of purification and scale not available. "),"") | U12: =IF(LEN(A12)>validOligoNameMaxLength,"DNA oligo name is too long. ","") | V12: =IF(AND(A12<>"",NOT(ISNUMBER(SUMPRODUCT(FIND(MID(A12,ROW(INDIRECT("1:"&LEN(A12))),1),validOligoNameCharacters))))),"DNA oligo name contains invalid characters. ","") | W12: =IF(AND(B12<>"",NOT(ISNUMBER(SUMPRODUCT(FIND(MID(B12,ROW(INDIRECT("1:"&LEN(B12))),1),validDnaSequenceCharacters))))),"DNA sequence contains invalid characters. ","") | X12: =OR(Z12,AA12) | Y12: =OR(Z12,AA12) | Z12: =AND(A12="Leerposition",P12>=2) | AA12: =AND(LEFT(A12,4)="NGS_",P12<=65,OR(D12="HPL",D12="HPD")) | AC12: =IF(AND(A12<>"",L12=""),"Physical condition not defined. ","") | AD12: =IF(AND(A12<>"",M12=""),"Datasheet not defined. ","") | AE12: =IF(AND(A12<>"",N12=""),"Aliquoting not defined. ","")
C13: =IF(B13<>"",LEN(SUBSTITUTE(SUBSTITUTE(B13," ",""),"*","")),"") | O13: =Q13 & R13 & U13 & V13 & W13 & S13 & T13 & AC13 & AD13 & AE13 | P13: =IF(B13<>"",LEN(SUBSTITUTE(SUBSTITUTE(B13," ",""),"*","")),"") | Q13: =IF(AND(A13="",B13<>""),"No name provided. ","") | R13: =IF(AND(A13<>"",B13=""),"No sequence provided. ","") | S13: =IF(AND(P13<>"",E13<>"",NOT(X13)),IF(AND(INDEX(validDnaScaleLowerSizeLimits,MATCH(E13,validDnaScale,0))<=$P13,$P13<=INDEX(validDnaScaleUpperSizeLimits,MATCH(E13,validDnaScale,0))),"","Sequence (length) not available in " & E13 & " scale. "),"") | T13: =IF(AND(P13<>"",E13<>"",NOT(Y13)),IF(AND(INDEX(validDnaPurificationLowerSizeLimits,MATCH(E13,validDnaScale,0),MATCH(D13,validDnaPurificationLowerSizeLimitsHeader,0))<=$P13,$P13<=INDEX(validDnaPurificationUpperSizeLimits,MATCH(E13,validDnaScale,0),MATCH(D13,validDnaPurificationUpperSizeLimitsHeader,0))),"","Combination of purification and scale not available. "),"") | U13: =IF(LEN(A13)>validOligoNameMaxLength,"DNA oligo name is too long. ","") | V13: =IF(AND(A13<>"",NOT(ISNUMBER(SUMPRODUCT(FIND(MID(A13,ROW(INDIRECT("1:"&LEN(A13))),1),validOligoNameCharacters))))),"DNA oligo name contains invalid characters. ","") | W13: =IF(AND(B13<>"",NOT(ISNUMBER(SUMPRODUCT(FIND(MID(B13,ROW(INDIRECT("1:"&LEN(B13))),1),validDnaSequenceCharacters))))),"DNA sequence contains invalid characters. ","") | X13: =OR(Z13,AA13) | Y13: =OR(Z13,AA13) | Z13: =AND(A13="Leerposition",P13>=2) | AA13: =AND(LEFT(A13,4)="NGS_",P13<=65,OR(D13="HPL",D13="HPD")) | AC13: =IF(AND(A13<>"",L13=""),"Physical condition not defined. ","") | AD13: =IF(AND(A13<>"",M13=""),"Datasheet not defined. ","") | AE13: =IF(AND(A13<>"",N13=""),"Aliquoting not defined. ","")
C14: =IF(B14<>"",LEN(SUBSTITUTE(SUBSTITUTE(B14," ",""),"*","")),"") | O14: =Q14 & R14 & U14 & V14 & W14 & S14 & T14 & AC14 & AD14 & AE14 | P14: =IF(B14<>"",LEN(SUBSTITUTE(SUBSTITUTE(B14," ",""),"*","")),"") | Q14: =IF(AND(A14="",B14<>""),"No name provided. ","") | R14: =IF(AND(A14<>"",B14=""),"No sequence provided. ","") | S14: =IF(AND(P14<>"",E14<>"",NOT(X14)),IF(AND(INDEX(validDnaScaleLowerSizeLimits,MATCH(E14,validDnaScale,0))<=$P14,$P14<=INDEX(validDnaScaleUpperSizeLimits,MATCH(E14,validDnaScale,0))),"","Sequence (length) not available in " & E14 & " scale. "),"") | T14: =IF(AND(P14<>"",E14<>"",NOT(Y14)),IF(AND(INDEX(validDnaPurificationLowerSizeLimits,MATCH(E14,validDnaScale,0),MATCH(D14,validDnaPurificationLowerSizeLimitsHeader,0))<=$P14,$P14<=INDEX(validDnaPurificationUpperSizeLimits,MATCH(E14,validDnaScale,0),MATCH(D14,validDnaPurificationUpperSizeLimitsHeader,0))),"","Combination of purification and scale not available. "),"") | U14: =IF(LEN(A14)>validOligoNameMaxLength,"DNA oligo name is too long. ","") | V14: =IF(AND(A14<>"",NOT(ISNUMBER(SUMPRODUCT(FIND(MID(A14,ROW(INDIRECT("1:"&LEN(A14))),1),validOligoNameCharacters))))),"DNA oligo name contains invalid characters. ","") | W14: =IF(AND(B14<>"",NOT(ISNUMBER(SUMPRODUCT(FIND(MID(B14,ROW(INDIRECT("1:"&LEN(B14))),1),validDnaSequenceCharacters))))),"DNA sequence contains invalid characters. ","") | X14: =OR(Z14,AA14) | Y14: =OR(Z14,AA14) | Z14: =AND(A14="Leerposition",P14>=2) | AA14: =AND(LEFT(A14,4)="NGS_",P14<=65,OR(D14="HPL",D14="HPD")) | AC14: =IF(AND(A14<>"",L14=""),"Physical condition not defined. ","") | AD14: =IF(AND(A14<>"",M14=""),"Datasheet not defined. ","") | AE14: =IF(AND(A14<>"",N14=""),"Aliquoting not defined. ","")
C15: =IF(B15<>"",LEN(SUBSTITUTE(SUBSTITUTE(B15," ",""),"*","")),"") | O15: =Q15 & R15 & U15 & V15 & W15 & S15 & T15 & AC15 & AD15 & AE15 | P15: =IF(B15<>"",LEN(SUBSTITUTE(SUBSTITUTE(B15," ",""),"*","")),"") | Q15: =IF(AND(A15="",B15<>""),"No name provided. ","") | R15: =IF(AND(A15<>"",B15=""),"No sequence provided. ","") | S15: =IF(AND(P15<>"",E15<>"",NOT(X15)),IF(AND(INDEX(validDnaScaleLowerSizeLimits,MATCH(E15,validDnaScale,0))<=$P15,$P15<=INDEX(validDnaScaleUpperSizeLimits,MATCH(E15,validDnaScale,0))),"","Sequence (length) not available in " & E15 & " scale. "),"") | T15: =IF(AND(P15<>"",E15<>"",NOT(Y15)),IF(AND(INDEX(validDnaPurificationLowerSizeLimits,MATCH(E15,validDnaScale,0),MATCH(D15,validDnaPurificationLowerSizeLimitsHeader,0))<=$P15,$P15<=INDEX(validDnaPurificationUpperSizeLimits,MATCH(E15,validDnaScale,0),MATCH(D15,validDnaPurificationUpperSizeLimitsHeader,0))),"","Combination of purification and scale not available. "),"") | U15: =IF(LEN(A15)>validOligoNameMaxLength,"DNA oligo name is too long. ","") | V15: =IF(AND(A15<>"",NOT(ISNUMBER(SUMPRODUCT(FIND(MID(A15,ROW(INDIRECT("1:"&LEN(A15))),1),validOligoNameCharacters))))),"DNA oligo name contains invalid characters. ","") | W15: =IF(AND(B15<>"",NOT(ISNUMBER(SUMPRODUCT(FIND(MID(B15,ROW(INDIRECT("1:"&LEN(B15))),1),validDnaSequenceCharacters))))),"DNA sequence contains invalid characters. ","") | X15: =OR(Z15,AA15) | Y15: =OR(Z15,AA15) | Z15: =AND(A15="Leerposition",P15>=2) | AA15: =AND(LEFT(A15,4)="NGS_",P15<=65,OR(D15="HPL",D15="HPD")) | AC15: =IF(AND(A15<>"",L15=""),"Physical condition not defined. ","") | AD15: =IF(AND(A15<>"",M15=""),"Datasheet not defined. ","") | AE15: =IF(AND(A15<>"",N15=""),"Aliquoting not defined. ","")
C16: =IF(B16<>"",LEN(SUBSTITUTE(SUBSTITUTE(B16," ",""),"*","")),"") | O16: =Q16 & R16 & U16 & V16 & W16 & S16 & T16 & AC16 & AD16 & AE16 | P16: =IF(B16<>"",LEN(SUBSTITUTE(SUBSTITUTE(B16," ",""),"*","")),"") | Q16: =IF(AND(A16="",B16<>""),"No name provided. ","") | R16: =IF(AND(A16<>"",B16=""),"No sequence provided. ","") | S16: =IF(AND(P16<>"",E16<>"",NOT(X16)),IF(AND(INDEX(validDnaScaleLowerSizeLimits,MATCH(E16,validDnaScale,0))<=$P16,$P16<=INDEX(validDnaScaleUpperSizeLimits,MATCH(E16,validDnaScale,0))),"","Sequence (length) not available in " & E16 & " scale. "),"") | T16: =IF(AND(P16<>"",E16<>"",NOT(Y16)),IF(AND(INDEX(validDnaPurificationLowerSizeLimits,MATCH(E16,validDnaScale,0),MATCH(D16,validDnaPurificationLowerSizeLimitsHeader,0))<=$P16,$P16<=INDEX(validDnaPurificationUpperSizeLimits,MATCH(E16,validDnaScale,0),MATCH(D16,validDnaPurificationUpperSizeLimitsHeader,0))),"","Combination of purification and scale not available. "),"") | U16: =IF(LEN(A16)>validOligoNameMaxLength,"DNA oligo name is too long. ","") | V16: =IF(AND(A16<>"",NOT(ISNUMBER(SUMPRODUCT(FIND(MID(A16,ROW(INDIRECT("1:"&LEN(A16))),1),validOligoNameCharacters))))),"DNA oligo name contains invalid characters. ","") | W16: =IF(AND(B16<>"",NOT(ISNUMBER(SUMPRODUCT(FIND(MID(B16,ROW(INDIRECT("1:"&LEN(B16))),1),validDnaSequenceCharacters))))),"DNA sequence contains invalid characters. ","") | X16: =OR(Z16,AA16) | Y16: =OR(Z16,AA16) | Z16: =AND(A16="Leerposition",P16>=2) | AA16: =AND(LEFT(A16,4)="NGS_",P16<=65,OR(D16="HPL",D16="HPD")) | AC16: =IF(AND(A16<>"",L16=""),"Physical condition not defined. ","") | AD16: =IF(AND(A16<>"",M16=""),"Datasheet not defined. ","") | AE16: =IF(AND(A16<>"",N16=""),"Aliquoting not defined. ","")
C17: =IF(B17<>"",LEN(SUBSTITUTE(SUBSTITUTE(B17," ",""),"*","")),"") | O17: =Q17 & R17 & U17 & V17 & W17 & S17 & T17 & AC17 & AD17 & AE17 | P17: =IF(B17<>"",LEN(SUBSTITUTE(SUBSTITUTE(B17," ",""),"*","")),"") | Q17: =IF(AND(A17="",B17<>""),"No name provided. ","") | R17: =IF(AND(A17<>"",B17=""),"No sequence provided. ","") | S17: =IF(AND(P17<>"",E17<>"",NOT(X17)),IF(AND(INDEX(validDnaScaleLowerSizeLimits,MATCH(E17,validDnaScale,0))<=$P17,$P17<=INDEX(validDnaScaleUpperSizeLimits,MATCH(E17,validDnaScale,0))),"","Sequence (length) not available in " & E17 & " scale. "),"") | T17: =IF(AND(P17<>"",E17<>"",NOT(Y17)),IF(AND(INDEX(validDnaPurificationLowerSizeLimits,MATCH(E17,validDnaScale,0),MATCH(D17,validDnaPurificationLowerSizeLimitsHeader,0))<=$P17,$P17<=INDEX(validDnaPurificationUpperSizeLimits,MATCH(E17,validDnaScale,0),MATCH(D17,validDnaPurificationUpperSizeLimitsHeader,0))),"","Combination of purification and scale not available. "),"") | U17: =IF(LEN(A17)>validOligoNameMaxLength,"DNA oligo name is too long. ","") | V17: =IF(AND(A17<>"",NOT(ISNUMBER(SUMPRODUCT(FIND(MID(A17,ROW(INDIRECT("1:"&LEN(A17))),1),validOligoNameCharacters))))),"DNA oligo name contains invalid characters. ","") | W17: =IF(AND(B17<>"",NOT(ISNUMBER(SUMPRODUCT(FIND(MID(B17,ROW(INDIRECT("1:"&LEN(B17))),1),validDnaSequenceCharacters))))),"DNA sequence contains invalid characters. ","") | X17: =OR(Z17,AA17) | Y17: =OR(Z17,AA17) | Z17: =AND(A17="Leerposition",P17>=2) | AA17: =AND(LEFT(A17,4)="NGS_",P17<=65,OR(D17="HPL",D17="HPD")) | AC17: =IF(AND(A17<>"",L17=""),"Physical condition not defined. ","") | AD17: =IF(AND(A17<>"",M17=""),"Datasheet not defined. ","") | AE17: =IF(AND(A17<>"",N17=""),"Aliquoting not defined. ","")
... C1153: =IF(B1153<>"",LEN(SUBSTITUTE(SUBSTITUTE(B1153," ",""),"*","")),"") | O1153: =Q1153 & R1153 & U1153 & V1153 & W1153 & S1153 & T1153 & AC1153 & AD1153 & AE1153 | P1153: =IF(B1153<>"",LEN(SUBSTITUTE(SUBSTITUTE(B1153," ",""),"*","")),"") | Q1153: =IF(AND(A1153="",B1153<>""),"No name provided. ","") | R1153: =IF(AND(A1153<>"",B1153=""),"No sequence provided. ","") | S1153: =IF(AND(P1153<>"",E1153<>"",NOT(X1153)),IF(AND(INDEX(validDnaScaleLowerSizeLimits,MATCH(E1153,validDnaScale,0))<=$P1153,$P1153<=INDEX(validDnaScaleUpperSizeLimits,MATCH(E1153,validDnaScale,0))),"","Sequence (length) not available in " & E1153 & " scale. "),"") | T1153: =IF(AND(P1153<>"",E1153<>"",NOT(Y1153)),IF(AND(INDEX(validDnaPurificationLowerSizeLimits,MATCH(E1153,validDnaScale,0),MATCH(D1153,validDnaPurificationLowerSizeLimitsHeader,0))<=$P1153,$P1153<=INDEX(validDnaPurificationUpperSizeLimits,MATCH(E1153,validDnaScale,0),MATCH(D1153,validDnaPurificationUpperSizeLimitsHeader,0))),"","Combination of purification and scale not available. "),"") | U1153: =IF(LEN(A1153)>validOligoNameMaxLength,"DNA oligo name is too long. ","") | V1153: =IF(AND(A1153<>"",NOT(ISNUMBER(SUMPRODUCT(FIND(MID(A1153,ROW(INDIRECT("1:"&LEN(A1153))),1),validOligoNameCharacters))))),"DNA oligo name contains invalid characters. ","") | W1153: =IF(AND(B1153<>"",NOT(ISNUMBER(SUMPRODUCT(FIND(MID(B1153,ROW(INDIRECT("1:"&LEN(B1153))),1),validDnaSequenceCharacters))))),"DNA sequence contains invalid characters. ","") | X1153: =OR(Z1153,AA1153) | Y1153: =OR(Z1153,AA1153) | Z1153: =AND(A1153="Leerposition",P1153>=2) | AA1153: =AND(LEFT(A1153,4)="NGS_",P1153<=65,OR(D1153="HPL",D1153="HPD")) | AC1153: =IF(AND(A1153<>"",L1153=""),"Physical condition not defined. ","") | AD1153: =IF(AND(A1153<>"",M1153=""),"Datasheet not defined. ","") | AE1153: =IF(AND(A1153<>"",N1153=""),"Aliquoting not defined. ","")

Sheet siRNA Order
A1: siRNA Name | B1: Sense Strand Sequence (Core Seq.; 5' -> 3') | C1: Sense Strand Overhang 5'-3' | D1: Antisense Strand Overhang 5'-3' | E1: Length | F1: siRNA Purification | G1: siRNA Scale | H1: Datasheet | J1: Length | K1: check empty name | L1: check empty sequence | M1: check name length | N1: check name characters | O1: check sequence characters | Q1: check datasheet
E2: =IF(B2<>"",LEN(SUBSTITUTE(SUBSTITUTE(B2," ",""),"*","")),"") | I2: =K2 & L2 & M2 & N2 & O2 & Q2 | J2: =IF(B2<>"",LEN(SUBSTITUTE(SUBSTITUTE(B2," ",""),"*","")),"") | K2: =IF(AND(A2="",B2<>""),"No name provided. ","") | L2: =IF(AND(A2<>"",B2=""),"No sequence provided. ","") | M2: =IF(LEN(A2)>validOligoNameMaxLength,"siRNA name is too long. ","") | N2: =IF(AND(A2<>"",NOT(ISNUMBER(SUMPRODUCT(FIND(MID(A2,ROW(INDIRECT("1:"&LEN(A2))),1),validOligoNameCharacters))))),"siRNA name contains invalid characters. ","") | O2: =IF(AND(B2<>"",NOT(ISNUMBER(SUMPRODUCT(FIND(MID(B2,ROW(INDIRECT("1:"&LEN(B2))),1),validSiRnaSequenceCharacters))))),"Sense strand sequence contains invalid characters. ","") | Q2: =IF(AND(A2<>"",H2=""),"Datasheet not defined. ","")
E3: =IF(B3<>"",LEN(SUBSTITUTE(SUBSTITUTE(B3," ",""),"*","")),"") | I3: =K3 & L3 & M3 & N3 & O3 & Q3 | J3: =IF(B3<>"",LEN(SUBSTITUTE(SUBSTITUTE(B3," ",""),"*","")),"") | K3: =IF(AND(A3="",B3<>""),"No name provided. ","") | L3: =IF(AND(A3<>"",B3=""),"No sequence provided. ","") | M3: =IF(LEN(A3)>validOligoNameMaxLength,"siRNA name is too long. ","") | N3: =IF(AND(A3<>"",NOT(ISNUMBER(SUMPRODUCT(FIND(MID(A3,ROW(INDIRECT("1:"&LEN(A3))),1),validOligoNameCharacters))))),"siRNA name contains invalid characters. ","") | O3: =IF(AND(B3<>"",NOT(ISNUMBER(SUMPRODUCT(FIND(MID(B3,ROW(INDIRECT("1:"&LEN(B3))),1),validSiRnaSequenceCharacters))))),"Sense strand sequence contains invalid characters. ","") | Q3: =IF(AND(A3<>"",H3=""),"Datasheet not defined. ","")
E4: =IF(B4<>"",LEN(SUBSTITUTE(SUBSTITUTE(B4," ",""),"*","")),"") | I4: =K4 & L4 & M4 & N4 & O4 & Q4 | J4: =IF(B4<>"",LEN(SUBSTITUTE(SUBSTITUTE(B4," ",""),"*","")),"") | K4: =IF(AND(A4="",B4<>""),"No name provided. ","") | L4: =IF(AND(A4<>"",B4=""),"No sequence provided. ","") | M4: =IF(LEN(A4)>validOligoNameMaxLength,"siRNA name is too long. ","") | N4: =IF(AND(A4<>"",NOT(ISNUMBER(SUMPRODUCT(FIND(MID(A4,ROW(INDIRECT("1:"&LEN(A4))),1),validOligoNameCharacters))))),"siRNA name contains invalid characters. ","") | O4: =IF(AND(B4<>"",NOT(ISNUMBER(SUMPRODUCT(FIND(MID(B4,ROW(INDIRECT("1:"&LEN(B4))),1),validSiRnaSequenceCharacters))))),"Sense strand sequence contains invalid characters. ","") | Q4: =IF(AND(A4<>"",H4=""),"Datasheet not defined. ","")
E5: =IF(B5<>"",LEN(SUBSTITUTE(SUBSTITUTE(B5," ",""),"*","")),"") | I5: =K5 & L5 & M5 & N5 & O5 & Q5 | J5: =IF(B5<>"",LEN(SUBSTITUTE(SUBSTITUTE(B5," ",""),"*","")),"") | K5: =IF(AND(A5="",B5<>""),"No name provided. ","") | L5: =IF(AND(A5<>"",B5=""),"No sequence provided. ","") | M5: =IF(LEN(A5)>validOligoNameMaxLength,"siRNA name is too long. ","") | N5: =IF(AND(A5<>"",NOT(ISNUMBER(SUMPRODUCT(FIND(MID(A5,ROW(INDIRECT("1:"&LEN(A5))),1),validOligoNameCharacters))))),"siRNA name contains invalid characters. ","") | O5: =IF(AND(B5<>"",NOT(ISNUMBER(SUMPRODUCT(FIND(MID(B5,ROW(INDIRECT("1:"&LEN(B5))),1),validSiRnaSequenceCharacters))))),"Sense strand sequence contains invalid characters. ","") | Q5: =IF(AND(A5<>"",H5=""),"Datasheet not defined. ","")
E6: =IF(B6<>"",LEN(SUBSTITUTE(SUBSTITUTE(B6," ",""),"*","")),"") | I6: =K6 & L6 & M6 & N6 & O6 & Q6 | J6: =IF(B6<>"",LEN(SUBSTITUTE(SUBSTITUTE(B6," ",""),"*","")),"") | K6: =IF(AND(A6="",B6<>""),"No name provided. ","") | L6: =IF(AND(A6<>"",B6=""),"No sequence provided. ","") | M6: =IF(LEN(A6)>validOligoNameMaxLength,"siRNA name is too long. ","") | N6: =IF(AND(A6<>"",NOT(ISNUMBER(SUMPRODUCT(FIND(MID(A6,ROW(INDIRECT("1:"&LEN(A6))),1),validOligoNameCharacters))))),"siRNA name contains invalid characters. ","") | O6: =IF(AND(B6<>"",NOT(ISNUMBER(SUMPRODUCT(FIND(MID(B6,ROW(INDIRECT("1:"&LEN(B6))),1),validSiRnaSequenceCharacters))))),"Sense strand sequence contains invalid characters. ","") | Q6: =IF(AND(A6<>"",H6=""),"Datasheet not defined. ","")
E7: =IF(B7<>"",LEN(SUBSTITUTE(SUBSTITUTE(B7," ",""),"*","")),"") | I7: =K7 & L7 & M7 & N7 & O7 & Q7 | J7: =IF(B7<>"",LEN(SUBSTITUTE(SUBSTITUTE(B7," ",""),"*","")),"") | K7: =IF(AND(A7="",B7<>""),"No name provided. ","") | L7: =IF(AND(A7<>"",B7=""),"No sequence provided. ","") | M7: =IF(LEN(A7)>validOligoNameMaxLength,"siRNA name is too long. ","") | N7: =IF(AND(A7<>"",NOT(ISNUMBER(SUMPRODUCT(FIND(MID(A7,ROW(INDIRECT("1:"&LEN(A7))),1),validOligoNameCharacters))))),"siRNA name contains invalid characters. ","") | O7: =IF(AND(B7<>"",NOT(ISNUMBER(SUMPRODUCT(FIND(MID(B7,ROW(INDIRECT("1:"&LEN(B7))),1),validSiRnaSequenceCharacters))))),"Sense strand sequence contains invalid characters. ","") | Q7: =IF(AND(A7<>"",H7=""),"Datasheet not defined. ","")
E8: =IF(B8<>"",LEN(SUBSTITUTE(SUBSTITUTE(B8," ",""),"*","")),"") | I8: =K8 & L8 & M8 & N8 & O8 & Q8 | J8: =IF(B8<>"",LEN(SUBSTITUTE(SUBSTITUTE(B8," ",""),"*","")),"") | K8: =IF(AND(A8="",B8<>""),"No name provided. ","") | L8: =IF(AND(A8<>"",B8=""),"No sequence provided. ","") | M8: =IF(LEN(A8)>validOligoNameMaxLength,"siRNA name is too long. ","") | N8: =IF(AND(A8<>"",NOT(ISNUMBER(SUMPRODUCT(FIND(MID(A8,ROW(INDIRECT("1:"&LEN(A8))),1),validOligoNameCharacters))))),"siRNA name contains invalid characters. ","") | O8: =IF(AND(B8<>"",NOT(ISNUMBER(SUMPRODUCT(FIND(MID(B8,ROW(INDIRECT("1:"&LEN(B8))),1),validSiRnaSequenceCharacters))))),"Sense strand sequence contains invalid characters. ","") | Q8: =IF(AND(A8<>"",H8=""),"Datasheet not defined. ","")
E9: =IF(B9<>"",LEN(SUBSTITUTE(SUBSTITUTE(B9," ",""),"*","")),"") | I9: =K9 & L9 & M9 & N9 & O9 & Q9 | J9: =IF(B9<>"",LEN(SUBSTITUTE(SUBSTITUTE(B9," ",""),"*","")),"") | K9: =IF(AND(A9="",B9<>""),"No name provided. ","") | L9: =IF(AND(A9<>"",B9=""),"No sequence provided. ","") | M9: =IF(LEN(A9)>validOligoNameMaxLength,"siRNA name is too long. ","") | N9: =IF(AND(A9<>"",NOT(ISNUMBER(SUMPRODUCT(FIND(MID(A9,ROW(INDIRECT("1:"&LEN(A9))),1),validOligoNameCharacters))))),"siRNA name contains invalid characters. ","") | O9: =IF(AND(B9<>"",NOT(ISNUMBER(SUMPRODUCT(FIND(MID(B9,ROW(INDIRECT("1:"&LEN(B9))),1),validSiRnaSequenceCharacters))))),"Sense strand sequence contains invalid characters. ","") | Q9: =IF(AND(A9<>"",H9=""),"Datasheet not defined. ","")
E10: =IF(B10<>"",LEN(SUBSTITUTE(SUBSTITUTE(B10," ",""),"*","")),"") | I10: =K10 & L10 & M10 & N10 & O10 & Q10 | J10: =IF(B10<>"",LEN(SUBSTITUTE(SUBSTITUTE(B10," ",""),"*","")),"") | K10: =IF(AND(A10="",B10<>""),"No name provided. ","") | L10: =IF(AND(A10<>"",B10=""),"No sequence provided. ","") | M10: =IF(LEN(A10)>validOligoNameMaxLength,"siRNA name is too long. ","") | N10: =IF(AND(A10<>"",NOT(ISNUMBER(SUMPRODUCT(FIND(MID(A10,ROW(INDIRECT("1:"&LEN(A10))),1),validOligoNameCharacters))))),"siRNA name contains invalid characters. ","") | O10: =IF(AND(B10<>"",NOT(ISNUMBER(SUMPRODUCT(FIND(MID(B10,ROW(INDIRECT("1:"&LEN(B10))),1),validSiRnaSequenceCharacters))))),"Sense strand sequence contains invalid characters. ","") | Q10: =IF(AND(A10<>"",H10=""),"Datasheet not defined. ","")
E11: =IF(B11<>"",LEN(SUBSTITUTE(SUBSTITUTE(B11," ",""),"*","")),"") | I11: =K11 & L11 & M11 & N11 & O11 & Q11 | J11: =IF(B11<>"",LEN(SUBSTITUTE(SUBSTITUTE(B11," ",""),"*","")),"") | K11: =IF(AND(A11="",B11<>""),"No name provided. ","") | L11: =IF(AND(A11<>"",B11=""),"No sequence provided. ","") | M11: =IF(LEN(A11)>validOligoNameMaxLength,"siRNA name is too long. ","") | N11: =IF(AND(A11<>"",NOT(ISNUMBER(SUMPRODUCT(FIND(MID(A11,ROW(INDIRECT("1:"&LEN(A11))),1),validOligoNameCharacters))))),"siRNA name contains invalid characters. ","") | O11: =IF(AND(B11<>"",NOT(ISNUMBER(SUMPRODUCT(FIND(MID(B11,ROW(INDIRECT("1:"&LEN(B11))),1),validSiRnaSequenceCharacters))))),"Sense strand sequence contains invalid characters. ","") | Q11: =IF(AND(A11<>"",H11=""),"Datasheet not defined. ","")
E12: =IF(B12<>"",LEN(SUBSTITUTE(SUBSTITUTE(B12," ",""),"*","")),"") | I12: =K12 & L12 & M12 & N12 & O12 & Q12 | J12: =IF(B12<>"",LEN(SUBSTITUTE(SUBSTITUTE(B12," ",""),"*","")),"") | K12: =IF(AND(A12="",B12<>""),"No name provided. ","") | L12: =IF(AND(A12<>"",B12=""),"No sequence provided. ","") | M12: =IF(LEN(A12)>validOligoNameMaxLength,"siRNA name is too long. ","") | N12: =IF(AND(A12<>"",NOT(ISNUMBER(SUMPRODUCT(FIND(MID(A12,ROW(INDIRECT("1:"&LEN(A12))),1),validOligoNameCharacters))))),"siRNA name contains invalid characters. ","") | O12: =IF(AND(B12<>"",NOT(ISNUMBER(SUMPRODUCT(FIND(MID(B12,ROW(INDIRECT("1:"&LEN(B12))),1),validSiRnaSequenceCharacters))))),"Sense strand sequence contains invalid characters. ","") | Q12: =IF(AND(A12<>"",H12=""),"Datasheet not defined. ","")
E13: =IF(B13<>"",LEN(SUBSTITUTE(SUBSTITUTE(B13," ",""),"*","")),"") | I13: =K13 & L13 & M13 & N13 & O13 & Q13 | J13: =IF(B13<>"",LEN(SUBSTITUTE(SUBSTITUTE(B13," ",""),"*","")),"") | K13: =IF(AND(A13="",B13<>""),"No name provided. ","") | L13: =IF(AND(A13<>"",B13=""),"No sequence provided. ","") | M13: =IF(LEN(A13)>validOligoNameMaxLength,"siRNA name is too long. ","") | N13: =IF(AND(A13<>"",NOT(ISNUMBER(SUMPRODUCT(FIND(MID(A13,ROW(INDIRECT("1:"&LEN(A13))),1),validOligoNameCharacters))))),"siRNA name contains invalid characters. ","") | O13: =IF(AND(B13<>"",NOT(ISNUMBER(SUMPRODUCT(FIND(MID(B13,ROW(INDIRECT("1:"&LEN(B13))),1),validSiRnaSequenceCharacters))))),"Sense strand sequence contains invalid characters. ","") | Q13: =IF(AND(A13<>"",H13=""),"Datasheet not defined. ","")
... E1153: =IF(B1153<>"",LEN(SUBSTITUTE(SUBSTITUTE(B1153," ",""),"*","")),"") | I1153: =K1153 & L1153 & M1153 & N1153 & O1153 & Q1153 | J1153: =IF(B1153<>"",LEN(SUBSTITUTE(SUBSTITUTE(B1153," ",""),"*","")),"") | K1153: =IF(AND(A1153="",B1153<>""),"No name provided. ","") | L1153: =IF(AND(A1153<>"",B1153=""),"No sequence provided. ","") | M1153: =IF(LEN(A1153)>validOligoNameMaxLength,"siRNA name is too long. ","") | N1153: =IF(AND(A1153<>"",NOT(ISNUMBER(SUMPRODUCT(FIND(MID(A1153,ROW(INDIRECT("1:"&LEN(A1153))),1),validOligoNameCharacters))))),"siRNA name contains invalid characters. ","") | O1153: =IF(AND(B1153<>"",NOT(ISNUMBER(SUMPRODUCT(FIND(MID(B1153,ROW(INDIRECT("1:"&LEN(B1153))),1),validSiRnaSequenceCharacters))))),"Sense strand sequence contains invalid characters. ","") | Q1153: =IF(AND(A1153<>"",H1153=""),"Datasheet not defined. ","")

Sheet RNA Order
A1: RNA Oligo name | B1: RNA Sequence (5' -> 3') | C1: Length | D1: RNA Purification | E1: RNA Scale | F1: 5' Modification | G1: Inner Modification (5) | H1: Inner Modification (6) | I1: Inner Modification (7) | J1: Inner Modification (8) | K1: 3' Modification | L1: Physical Condition | M1: Datasheet | N1: Aliquots | P1: Length | Q1: check empty name | R1: check empty sequence | S1: check scale | T1: check scale/purification | U1: check name length | V1: check name characters | W1: check sequence characters | X1: allowed exception scale | Y1: allowed exception scale/purification | Z1: allowed condition 1 | AC1: check physical condition | AD1: check datasheet | AE1: check aliquot
O2: =Q2 & R2 & U2 & V2 & W2 & S2 & T2 & AC2 & AD2 & AE2 | P2: =IF(B2<>"",LEN(SUBSTITUTE(SUBSTITUTE(B2," ",""),"*","")),"") | Q2: =IF(AND(A2="",B2<>""),"No name provided. ","") | R2: =IF(AND(A2<>"",B2=""),"No sequence provided. ","") | S2: =IF(AND(P2<>"",E2<>"",NOT(X2)),IF(AND(INDEX(validRnaScaleLowerSizeLimits,MATCH(E2,validRnaScale,0))<=$P2,$P2<=INDEX(validRnaScaleUpperSizeLimits,MATCH(E2,validRnaScale,0))),"","Sequence (length) not available in " & E2 & " scale. "),"") | T2: =IF(AND(P2<>"",E2<>"",NOT(Y2)),IF(AND(INDEX(validRnaPurificationLowerSizeLimits,MATCH(E2,validRnaScale,0),MATCH(D2,validRnaPurificationLowerSizeLimitsHeader,0))<=$P2,$P2<=INDEX(validRnaPurificationUpperSizeLimits,MATCH(E2,validRnaScale,0),MATCH(D2,validRnaPurificationUpperSizeLimitsHeader,0))),"","Combination of purification and scale not available. "),"") | U2: =IF(LEN(A2)>validOligoNameMaxLength,"RNA oligo name is too long. ","") | V2: =IF(AND(A2<>"",NOT(ISNUMBER(SUMPRODUCT(FIND(MID(A2,ROW(INDIRECT("1:"&LEN(A2))),1),validOligoNameCharacters))))),"RNA oligo name contains invalid characters. ","") | W2: =IF(AND(B2<>"",NOT(ISNUMBER(SUMPRODUCT(FIND(MID(B2,ROW(INDIRECT("1:"&LEN(B2))),1),validRnaSequenceCharacters))))),"RNA sequence contains invalid characters. ","") | X2: =OR(Z2) | Y2: =OR(Z2) | Z2: =AND(A2="Leerposition",P2>=2) | AC2: =IF(AND(A2<>"",L2=""),"Physical condition not defined. ","") | AD2: =IF(AND(A2<>"",M2=""),"Datasheet not defined. ","") | AE2: =IF(AND(A2<>"",N2=""),"Aliquoting not defined. ","")
C3: =IF(B3<>"",LEN(SUBSTITUTE(SUBSTITUTE(B3," ",""),"*","")),"") | O3: =Q3 & R3 & U3 & V3 & W3 & S3 & T3 & AC3 & AD3 & AE3 | P3: =IF(B3<>"",LEN(SUBSTITUTE(SUBSTITUTE(B3," ",""),"*","")),"") | Q3: =IF(AND(A3="",B3<>""),"No name provided. ","") | R3: =IF(AND(A3<>"",B3=""),"No sequence provided. ","") | S3: =IF(AND(P3<>"",E3<>"",NOT(X3)),IF(AND(INDEX(validRnaScaleLowerSizeLimits,MATCH(E3,validRnaScale,0))<=$P3,$P3<=INDEX(validRnaScaleUpperSizeLimits,MATCH(E3,validRnaScale,0))),"","Sequence (length) not available in " & E3 & " scale. "),"") | T3: =IF(AND(P3<>"",E3<>"",NOT(Y3)),IF(AND(INDEX(validRnaPurificationLowerSizeLimits,MATCH(E3,validRnaScale,0),MATCH(D3,validRnaPurificationLowerSizeLimitsHeader,0))<=$P3,$P3<=INDEX(validRnaPurificationUpperSizeLimits,MATCH(E3,validRnaScale,0),MATCH(D3,validRnaPurificationUpperSizeLimitsHeader,0))),"","Combination of purification and scale not available. "),"") | U3: =IF(LEN(A3)>validOligoNameMaxLength,"RNA oligo name is too long. ","") | V3: =IF(AND(A3<>"",NOT(ISNUMBER(SUMPRODUCT(FIND(MID(A3,ROW(INDIRECT("1:"&LEN(A3))),1),validOligoNameCharacters))))),"RNA oligo name contains invalid characters. ","") | W3: =IF(AND(B3<>"",NOT(ISNUMBER(SUMPRODUCT(FIND(MID(B3,ROW(INDIRECT("1:"&LEN(B3))),1),validRnaSequenceCharacters))))),"RNA sequence contains invalid characters. ","") | X3: =OR(Z3) | Y3: =OR(Z3) | Z3: =AND(A3="Leerposition",P3>=2) | AC3: =IF(AND(A3<>"",L3=""),"Physical condition not defined. ","") | AD3: =IF(AND(A3<>"",M3=""),"Datasheet not defined. ","") | AE3: =IF(AND(A3<>"",N3=""),"Aliquoting not defined. ","")
C4: =IF(B4<>"",LEN(SUBSTITUTE(SUBSTITUTE(B4," ",""),"*","")),"") | O4: =Q4 & R4 & U4 & V4 & W4 & S4 & T4 & AC4 & AD4 & AE4 | P4: =IF(B4<>"",LEN(SUBSTITUTE(SUBSTITUTE(B4," ",""),"*","")),"") | Q4: =IF(AND(A4="",B4<>""),"No name provided. ","") | R4: =IF(AND(A4<>"",B4=""),"No sequence provided. ","") | S4: =IF(AND(P4<>"",E4<>"",NOT(X4)),IF(AND(INDEX(validRnaScaleLowerSizeLimits,MATCH(E4,validRnaScale,0))<=$P4,$P4<=INDEX(validRnaScaleUpperSizeLimits,MATCH(E4,validRnaScale,0))),"","Sequence (length) not available in " & E4 & " scale. "),"") | T4: =IF(AND(P4<>"",E4<>"",NOT(Y4)),IF(AND(INDEX(validRnaPurificationLowerSizeLimits,MATCH(E4,validRnaScale,0),MATCH(D4,validRnaPurificationLowerSizeLimitsHeader,0))<=$P4,$P4<=INDEX(validRnaPurificationUpperSizeLimits,MATCH(E4,validRnaScale,0),MATCH(D4,validRnaPurificationUpperSizeLimitsHeader,0))),"","Combination of purification and scale not available. "),"") | U4: =IF(LEN(A4)>validOligoNameMaxLength,"RNA oligo name is too long. ","") | V4: =IF(AND(A4<>"",NOT(ISNUMBER(SUMPRODUCT(FIND(MID(A4,ROW(INDIRECT("1:"&LEN(A4))),1),validOligoNameCharacters))))),"RNA oligo name contains invalid characters. ","") | W4: =IF(AND(B4<>"",NOT(ISNUMBER(SUMPRODUCT(FIND(MID(B4,ROW(INDIRECT("1:"&LEN(B4))),1),validRnaSequenceCharacters))))),"RNA sequence contains invalid characters. ","") | X4: =OR(Z4) | Y4: =OR(Z4) | Z4: =AND(A4="Leerposition",P4>=2) | AC4: =IF(AND(A4<>"",L4=""),"Physical condition not defined. ","") | AD4: =IF(AND(A4<>"",M4=""),"Datasheet not defined. ","") | AE4: =IF(AND(A4<>"",N4=""),"Aliquoting not defined. ","")
C5: =IF(B5<>"",LEN(SUBSTITUTE(SUBSTITUTE(B5," ",""),"*","")),"") | O5: =Q5 & R5 & U5 & V5 & W5 & S5 & T5 & AC5 & AD5 & AE5 | P5: =IF(B5<>"",LEN(SUBSTITUTE(SUBSTITUTE(B5," ",""),"*","")),"") | Q5: =IF(AND(A5="",B5<>""),"No name provided. ","") | R5: =IF(AND(A5<>"",B5=""),"No sequence provided. ","") | S5: =IF(AND(P5<>"",E5<>"",NOT(X5)),IF(AND(INDEX(validRnaScaleLowerSizeLimits,MATCH(E5,validRnaScale,0))<=$P5,$P5<=INDEX(validRnaScaleUpperSizeLimits,MATCH(E5,validRnaScale,0))),"","Sequence (length) not available in " & E5 & " scale. "),"") | T5: =IF(AND(P5<>"",E5<>"",NOT(Y5)),IF(AND(INDEX(validRnaPurificationLowerSizeLimits,MATCH(E5,validRnaScale,0),MATCH(D5,validRnaPurificationLowerSizeLimitsHeader,0))<=$P5,$P5<=INDEX(validRnaPurificationUpperSizeLimits,MATCH(E5,validRnaScale,0),MATCH(D5,validRnaPurificationUpperSizeLimitsHeader,0))),"","Combination of purification and scale not available. "),"") | U5: =IF(LEN(A5)>validOligoNameMaxLength,"RNA oligo name is too long. ","") | V5: =IF(AND(A5<>"",NOT(ISNUMBER(SUMPRODUCT(FIND(MID(A5,ROW(INDIRECT("1:"&LEN(A5))),1),validOligoNameCharacters))))),"RNA oligo name contains invalid characters. ","") | W5: =IF(AND(B5<>"",NOT(ISNUMBER(SUMPRODUCT(FIND(MID(B5,ROW(INDIRECT("1:"&LEN(B5))),1),validRnaSequenceCharacters))))),"RNA sequence contains invalid characters. ","") | X5: =OR(Z5) | Y5: =OR(Z5) | Z5: =AND(A5="Leerposition",P5>=2) | AC5: =IF(AND(A5<>"",L5=""),"Physical condition not defined. ","") | AD5: =IF(AND(A5<>"",M5=""),"Datasheet not defined. ","") | AE5: =IF(AND(A5<>"",N5=""),"Aliquoting not defined. ","")
C6: =IF(B6<>"",LEN(SUBSTITUTE(SUBSTITUTE(B6," ",""),"*","")),"") | O6: =Q6 & R6 & U6 & V6 & W6 & S6 & T6 & AC6 & AD6 & AE6 | P6: =IF(B6<>"",LEN(SUBSTITUTE(SUBSTITUTE(B6," ",""),"*","")),"") | Q6: =IF(AND(A6="",B6<>""),"No name provided. ","") | R6: =IF(AND(A6<>"",B6=""),"No sequence provided. ","") | S6: =IF(AND(P6<>"",E6<>"",NOT(X6)),IF(AND(INDEX(validRnaScaleLowerSizeLimits,MATCH(E6,validRnaScale,0))<=$P6,$P6<=INDEX(validRnaScaleUpperSizeLimits,MATCH(E6,validRnaScale,0))),"","Sequence (length) not available in " & E6 & " scale. "),"") | T6: =IF(AND(P6<>"",E6<>"",NOT(Y6)),IF(AND(INDEX(validRnaPurificationLowerSizeLimits,MATCH(E6,validRnaScale,0),MATCH(D6,validRnaPurificationLowerSizeLimitsHeader,0))<=$P6,$P6<=INDEX(validRnaPurificationUpperSizeLimits,MATCH(E6,validRnaScale,0),MATCH(D6,validRnaPurificationUpperSizeLimitsHeader,0))),"","Combination of purification and scale not available. "),"") | U6: =IF(LEN(A6)>validOligoNameMaxLength,"RNA oligo name is too long. ","") | V6: =IF(AND(A6<>"",NOT(ISNUMBER(SUMPRODUCT(FIND(MID(A6,ROW(INDIRECT("1:"&LEN(A6))),1),validOligoNameCharacters))))),"RNA oligo name contains invalid characters. ","") | W6: =IF(AND(B6<>"",NOT(ISNUMBER(SUMPRODUCT(FIND(MID(B6,ROW(INDIRECT("1:"&LEN(B6))),1),validRnaSequenceCharacters))))),"RNA sequence contains invalid characters. ","") | X6: =OR(Z6) | Y6: =OR(Z6) | Z6: =AND(A6="Leerposition",P6>=2) | AC6: =IF(AND(A6<>"",L6=""),"Physical condition not defined. ","") | AD6: =IF(AND(A6<>"",M6=""),"Datasheet not defined. ","") | AE6: =IF(AND(A6<>"",N6=""),"Aliquoting not defined. ","")
C7: =IF(B7<>"",LEN(SUBSTITUTE(SUBSTITUTE(B7," ",""),"*","")),"") | O7: =Q7 & R7 & U7 & V7 & W7 & S7 & T7 & AC7 & AD7 & AE7 | P7: =IF(B7<>"",LEN(SUBSTITUTE(SUBSTITUTE(B7," ",""),"*","")),"") | Q7: =IF(AND(A7="",B7<>""),"No name provided. ","") | R7: =IF(AND(A7<>"",B7=""),"No sequence provided. ","") | S7: =IF(AND(P7<>"",E7<>"",NOT(X7)),IF(AND(INDEX(validRnaScaleLowerSizeLimits,MATCH(E7,validRnaScale,0))<=$P7,$P7<=INDEX(validRnaScaleUpperSizeLimits,MATCH(E7,validRnaScale,0))),"","Sequence (length) not available in " & E7 & " scale. "),"") | T7: =IF(AND(P7<>"",E7<>"",NOT(Y7)),IF(AND(INDEX(validRnaPurificationLowerSizeLimits,MATCH(E7,validRnaScale,0),MATCH(D7,validRnaPurificationLowerSizeLimitsHeader,0))<=$P7,$P7<=INDEX(validRnaPurificationUpperSizeLimits,MATCH(E7,validRnaScale,0),MATCH(D7,validRnaPurificationUpperSizeLimitsHeader,0))),"","Combination of purification and scale not available. "),"") | U7: =IF(LEN(A7)>validOligoNameMaxLength,"RNA oligo name is too long. ","") | V7: =IF(AND(A7<>"",NOT(ISNUMBER(SUMPRODUCT(FIND(MID(A7,ROW(INDIRECT("1:"&LEN(A7))),1),validOligoNameCharacters))))),"RNA oligo name contains invalid characters. ","") | W7: =IF(AND(B7<>"",NOT(ISNUMBER(SUMPRODUCT(FIND(MID(B7,ROW(INDIRECT("1:"&LEN(B7))),1),validRnaSequenceCharacters))))),"RNA sequence contains invalid characters. ","") | X7: =OR(Z7) | Y7: =OR(Z7) | Z7: =AND(A7="Leerposition",P7>=2) | AC7: =IF(AND(A7<>"",L7=""),"Physical condition not defined. ","") | AD7: =IF(AND(A7<>"",M7=""),"Datasheet not defined. ","") | AE7: =IF(AND(A7<>"",N7=""),"Aliquoting not defined. ","")
C8: =IF(B8<>"",LEN(SUBSTITUTE(SUBSTITUTE(B8," ",""),"*","")),"") | O8: =Q8 & R8 & U8 & V8 & W8 & S8 & T8 & AC8 & AD8 & AE8 | P8: =IF(B8<>"",LEN(SUBSTITUTE(SUBSTITUTE(B8," ",""),"*","")),"") | Q8: =IF(AND(A8="",B8<>""),"No name provided. ","") | R8: =IF(AND(A8<>"",B8=""),"No sequence provided. ","") | S8: =IF(AND(P8<>"",E8<>"",NOT(X8)),IF(AND(INDEX(validRnaScaleLowerSizeLimits,MATCH(E8,validRnaScale,0))<=$P8,$P8<=INDEX(validRnaScaleUpperSizeLimits,MATCH(E8,validRnaScale,0))),"","Sequence (length) not available in " & E8 & " scale. "),"") | T8: =IF(AND(P8<>"",E8<>"",NOT(Y8)),IF(AND(INDEX(validRnaPurificationLowerSizeLimits,MATCH(E8,validRnaScale,0),MATCH(D8,validRnaPurificationLowerSizeLimitsHeader,0))<=$P8,$P8<=INDEX(validRnaPurificationUpperSizeLimits,MATCH(E8,validRnaScale,0),MATCH(D8,validRnaPurificationUpperSizeLimitsHeader,0))),"","Combination of purification and scale not available. "),"") | U8: =IF(LEN(A8)>validOligoNameMaxLength,"RNA oligo name is too long. ","") | V8: =IF(AND(A8<>"",NOT(ISNUMBER(SUMPRODUCT(FIND(MID(A8,ROW(INDIRECT("1:"&LEN(A8))),1),validOligoNameCharacters))))),"RNA oligo name contains invalid characters. ","") | W8: =IF(AND(B8<>"",NOT(ISNUMBER(SUMPRODUCT(FIND(MID(B8,ROW(INDIRECT("1:"&LEN(B8))),1),validRnaSequenceCharacters))))),"RNA sequence contains invalid characters. ","") | X8: =OR(Z8) | Y8: =OR(Z8) | Z8: =AND(A8="Leerposition",P8>=2) | AC8: =IF(AND(A8<>"",L8=""),"Physical condition not defined. ","") | AD8: =IF(AND(A8<>"",M8=""),"Datasheet not defined. ","") | AE8: =IF(AND(A8<>"",N8=""),"Aliquoting not defined. ","")
C9: =IF(B9<>"",LEN(SUBSTITUTE(SUBSTITUTE(B9," ",""),"*","")),"") | O9: =Q9 & R9 & U9 & V9 & W9 & S9 & T9 & AC9 & AD9 & AE9 | P9: =IF(B9<>"",LEN(SUBSTITUTE(SUBSTITUTE(B9," ",""),"*","")),"") | Q9: =IF(AND(A9="",B9<>""),"No name provided. ","") | R9: =IF(AND(A9<>"",B9=""),"No sequence provided. ","") | S9: =IF(AND(P9<>"",E9<>"",NOT(X9)),IF(AND(INDEX(validRnaScaleLowerSizeLimits,MATCH(E9,validRnaScale,0))<=$P9,$P9<=INDEX(validRnaScaleUpperSizeLimits,MATCH(E9,validRnaScale,0))),"","Sequence (length) not available in " & E9 & " scale. "),"") | T9: =IF(AND(P9<>"",E9<>"",NOT(Y9)),IF(AND(INDEX(validRnaPurificationLowerSizeLimits,MATCH(E9,validRnaScale,0),MATCH(D9,validRnaPurificationLowerSizeLimitsHeader,0))<=$P9,$P9<=INDEX(validRnaPurificationUpperSizeLimits,MATCH(E9,validRnaScale,0),MATCH(D9,validRnaPurificationUpperSizeLimitsHeader,0))),"","Combination of purification and scale not available. "),"") | U9: =IF(LEN(A9)>validOligoNameMaxLength,"RNA oligo name is too long. ","") | V9: =IF(AND(A9<>"",NOT(ISNUMBER(SUMPRODUCT(FIND(MID(A9,ROW(INDIRECT("1:"&LEN(A9))),1),validOligoNameCharacters))))),"RNA oligo name contains invalid characters. ","") | W9: =IF(AND(B9<>"",NOT(ISNUMBER(SUMPRODUCT(FIND(MID(B9,ROW(INDIRECT("1:"&LEN(B9))),1),validRnaSequenceCharacters))))),"RNA sequence contains invalid characters. ","") | X9: =OR(Z9) | Y9: =OR(Z9) | Z9: =AND(A9="Leerposition",P9>=2) | AC9: =IF(AND(A9<>"",L9=""),"Physical condition not defined. ","") | AD9: =IF(AND(A9<>"",M9=""),"Datasheet not defined. ","") | AE9: =IF(AND(A9<>"",N9=""),"Aliquoting not defined. ","")
C10: =IF(B10<>"",LEN(SUBSTITUTE(SUBSTITUTE(B10," ",""),"*","")),"") | O10: =Q10 & R10 & U10 & V10 & W10 & S10 & T10 & AC10 & AD10 & AE10 | P10: =IF(B10<>"",LEN(SUBSTITUTE(SUBSTITUTE(B10," ",""),"*","")),"") | Q10: =IF(AND(A10="",B10<>""),"No name provided. ","") | R10: =IF(AND(A10<>"",B10=""),"No sequence provided. ","") | S10: =IF(AND(P10<>"",E10<>"",NOT(X10)),IF(AND(INDEX(validRnaScaleLowerSizeLimits,MATCH(E10,validRnaScale,0))<=$P10,$P10<=INDEX(validRnaScaleUpperSizeLimits,MATCH(E10,validRnaScale,0))),"","Sequence (length) not available in " & E10 & " scale. "),"") | T10: =IF(AND(P10<>"",E10<>"",NOT(Y10)),IF(AND(INDEX(validRnaPurificationLowerSizeLimits,MATCH(E10,validRnaScale,0),MATCH(D10,validRnaPurificationLowerSizeLimitsHeader,0))<=$P10,$P10<=INDEX(validRnaPurificationUpperSizeLimits,MATCH(E10,validRnaScale,0),MATCH(D10,validRnaPurificationUpperSizeLimitsHeader,0))),"","Combination of purification and scale not available. "),"") | U10: =IF(LEN(A10)>validOligoNameMaxLength,"RNA oligo name is too long. ","") | V10: =IF(AND(A10<>"",NOT(ISNUMBER(SUMPRODUCT(FIND(MID(A10,ROW(INDIRECT("1:"&LEN(A10))),1),validOligoNameCharacters))))),"RNA oligo name contains invalid characters. ","") | W10: =IF(AND(B10<>"",NOT(ISNUMBER(SUMPRODUCT(FIND(MID(B10,ROW(INDIRECT("1:"&LEN(B10))),1),validRnaSequenceCharacters))))),"RNA sequence contains invalid characters. ","") | X10: =OR(Z10) | Y10: =OR(Z10) | Z10: =AND(A10="Leerposition",P10>=2) | AC10: =IF(AND(A10<>"",L10=""),"Physical condition not defined. ","") | AD10: =IF(AND(A10<>"",M10=""),"Datasheet not defined. ","") | AE10: =IF(AND(A10<>"",N10=""),"Aliquoting not defined. ","")
C11: =IF(B11<>"",LEN(SUBSTITUTE(SUBSTITUTE(B11," ",""),"*","")),"") | O11: =Q11 & R11 & U11 & V11 & W11 & S11 & T11 & AC11 & AD11 & AE11 | P11: =IF(B11<>"",LEN(SUBSTITUTE(SUBSTITUTE(B11," ",""),"*","")),"") | Q11: =IF(AND(A11="",B11<>""),"No name provided. ","") | R11: =IF(AND(A11<>"",B11=""),"No sequence provided. ","") | S11: =IF(AND(P11<>"",E11<>"",NOT(X11)),IF(AND(INDEX(validRnaScaleLowerSizeLimits,MATCH(E11,validRnaScale,0))<=$P11,$P11<=INDEX(validRnaScaleUpperSizeLimits,MATCH(E11,validRnaScale,0))),"","Sequence (length) not available in " & E11 & " scale. "),"") | T11: =IF(AND(P11<>"",E11<>"",NOT(Y11)),IF(AND(INDEX(validRnaPurificationLowerSizeLimits,MATCH(E11,validRnaScale,0),MATCH(D11,validRnaPurificationLowerSizeLimitsHeader,0))<=$P11,$P11<=INDEX(validRnaPurificationUpperSizeLimits,MATCH(E11,validRnaScale,0),MATCH(D11,validRnaPurificationUpperSizeLimitsHeader,0))),"","Combination of purification and scale not available. "),"") | U11: =IF(LEN(A11)>validOligoNameMaxLength,"RNA oligo name is too long. ","") | V11: =IF(AND(A11<>"",NOT(ISNUMBER(SUMPRODUCT(FIND(MID(A11,ROW(INDIRECT("1:"&LEN(A11))),1),validOligoNameCharacters))))),"RNA oligo name contains invalid characters. ","") | W11: =IF(AND(B11<>"",NOT(ISNUMBER(SUMPRODUCT(FIND(MID(B11,ROW(INDIRECT("1:"&LEN(B11))),1),validRnaSequenceCharacters))))),"RNA sequence contains invalid characters. ","") | X11: =OR(Z11) | Y11: =OR(Z11) | Z11: =AND(A11="Leerposition",P11>=2) | AC11: =IF(AND(A11<>"",L11=""),"Physical condition not defined. ","") | AD11: =IF(AND(A11<>"",M11=""),"Datasheet not defined. ","") | AE11: =IF(AND(A11<>"",N11=""),"Aliquoting not defined. ","")
C12: =IF(B12<>"",LEN(SUBSTITUTE(SUBSTITUTE(B12," ",""),"*","")),"") | O12: =Q12 & R12 & U12 & V12 & W12 & S12 & T12 & AC12 & AD12 & AE12 | P12: =IF(B12<>"",LEN(SUBSTITUTE(SUBSTITUTE(B12," ",""),"*","")),"") | Q12: =IF(AND(A12="",B12<>""),"No name provided. ","") | R12: =IF(AND(A12<>"",B12=""),"No sequence provided. ","") | S12: =IF(AND(P12<>"",E12<>"",NOT(X12)),IF(AND(INDEX(validRnaScaleLowerSizeLimits,MATCH(E12,validRnaScale,0))<=$P12,$P12<=INDEX(validRnaScaleUpperSizeLimits,MATCH(E12,validRnaScale,0))),"","Sequence (length) not available in " & E12 & " scale. "),"") | T12: =IF(AND(P12<>"",E12<>"",NOT(Y12)),IF(AND(INDEX(validRnaPurificationLowerSizeLimits,MATCH(E12,validRnaScale,0),MATCH(D12,validRnaPurificationLowerSizeLimitsHeader,0))<=$P12,$P12<=INDEX(validRnaPurificationUpperSizeLimits,MATCH(E12,validRnaScale,0),MATCH(D12,validRnaPurificationUpperSizeLimitsHeader,0))),"","Combination of purification and scale not available. "),"") | U12: =IF(LEN(A12)>validOligoNameMaxLength,"RNA oligo name is too long. ","") | V12: =IF(AND(A12<>"",NOT(ISNUMBER(SUMPRODUCT(FIND(MID(A12,ROW(INDIRECT("1:"&LEN(A12))),1),validOligoNameCharacters))))),"RNA oligo name contains invalid characters. ","") | W12: =IF(AND(B12<>"",NOT(ISNUMBER(SUMPRODUCT(FIND(MID(B12,ROW(INDIRECT("1:"&LEN(B12))),1),validRnaSequenceCharacters))))),"RNA sequence contains invalid characters. ","") | X12: =OR(Z12) | Y12: =OR(Z12) | Z12: =AND(A12="Leerposition",P12>=2) | AC12: =IF(AND(A12<>"",L12=""),"Physical condition not defined. ","") | AD12: =IF(AND(A12<>"",M12=""),"Datasheet not defined. ","") | AE12: =IF(AND(A12<>"",N12=""),"Aliquoting not defined. ","")
